Traceback (most recent call last):
  File "/opt/hostedtoolcache/Python/3.8.13/x64/lib/python3.8/site-packages/urllib3/connectionpool.py", line 703, in urlopen
    httplib_response = self._make_request(
  File "/opt/hostedtoolcache/Python/3.8.13/x64/lib/python3.8/site-packages/urllib3/connectionpool.py", line 386, in _make_request
    self._validate_conn(conn)
  File "/opt/hostedtoolcache/Python/3.8.13/x64/lib/python3.8/site-packages/urllib3/connectionpool.py", line 1040, in _validate_conn
    conn.connect()
  File "/opt/hostedtoolcache/Python/3.8.13/x64/lib/python3.8/site-packages/urllib3/connection.py", line 414, in connect
    self.sock = ssl_wrap_socket(
  File "/opt/hostedtoolcache/Python/3.8.13/x64/lib/python3.8/site-packages/urllib3/util/ssl_.py", line 449, in ssl_wrap_socket
    ssl_sock = _ssl_wrap_socket_impl(
  File "/opt/hostedtoolcache/Python/3.8.13/x64/lib/python3.8/site-packages/urllib3/util/ssl_.py", line 493, in _ssl_wrap_socket_impl
    return ssl_context.wrap_socket(sock, server_hostname=server_hostname)
  File "/opt/hostedtoolcache/Python/3.8.13/x64/lib/python3.8/ssl.py", line 500, in wrap_socket
    return self.sslsocket_class._create(
  File "/opt/hostedtoolcache/Python/3.8.13/x64/lib/python3.8/ssl.py", line 1040, in _create
    self.do_handshake()
  File "/opt/hostedtoolcache/Python/3.8.13/x64/lib/python3.8/ssl.py", line 1309, in do_handshake
    self._sslobj.do_handshake()
ConnectionResetError: [Errno 104] Connection reset by peer

During handling of the above exception, another exception occurred:

Traceback (most recent call last):
  File "/opt/hostedtoolcache/Python/3.8.13/x64/lib/python3.8/site-packages/requests/adapters.py", line 489, in send
    resp = conn.urlopen(
  File "/opt/hostedtoolcache/Python/3.8.13/x64/lib/python3.8/site-packages/urllib3/connectionpool.py", line 785, in urlopen
    retries = retries.increment(
  File "/opt/hostedtoolcache/Python/3.8.13/x64/lib/python3.8/site-packages/urllib3/util/retry.py", line 550, in increment
    raise six.reraise(type(error), error, _stacktrace)
  File "/opt/hostedtoolcache/Python/3.8.13/x64/lib/python3.8/site-packages/urllib3/packages/six.py", line 769, in reraise
    raise value.with_traceback(tb)
  File "/opt/hostedtoolcache/Python/3.8.13/x64/lib/python3.8/site-packages/urllib3/connectionpool.py", line 703, in urlopen
    httplib_response = self._make_request(
  File "/opt/hostedtoolcache/Python/3.8.13/x64/lib/python3.8/site-packages/urllib3/connectionpool.py", line 386, in _make_request
    self._validate_conn(conn)
  File "/opt/hostedtoolcache/Python/3.8.13/x64/lib/python3.8/site-packages/urllib3/connectionpool.py", line 1040, in _validate_conn
    conn.connect()
  File "/opt/hostedtoolcache/Python/3.8.13/x64/lib/python3.8/site-packages/urllib3/connection.py", line 414, in connect
    self.sock = ssl_wrap_socket(
  File "/opt/hostedtoolcache/Python/3.8.13/x64/lib/python3.8/site-packages/urllib3/util/ssl_.py", line 449, in ssl_wrap_socket
    ssl_sock = _ssl_wrap_socket_impl(
  File "/opt/hostedtoolcache/Python/3.8.13/x64/lib/python3.8/site-packages/urllib3/util/ssl_.py", line 493, in _ssl_wrap_socket_impl
    return ssl_context.wrap_socket(sock, server_hostname=server_hostname)
  File "/opt/hostedtoolcache/Python/3.8.13/x64/lib/python3.8/ssl.py", line 500, in wrap_socket
    return self.sslsocket_class._create(
  File "/opt/hostedtoolcache/Python/3.8.13/x64/lib/python3.8/ssl.py", line 1040, in _create
    self.do_handshake()
  File "/opt/hostedtoolcache/Python/3.8.13/x64/lib/python3.8/ssl.py", line 1309, in do_handshake
    self._sslobj.do_handshake()
urllib3.exceptions.ProtocolError: ('Connection aborted.', ConnectionResetError(104, 'Connection reset by peer'))

During handling of the above exception, another exception occurred:

Traceback (most recent call last):
  File "download.py", line 12, in <module>
    cg = cggr.CGGR()
  File "/home/runner/work/CGGR/CGGR/cggr.py", line 8, in __init__
    self.GetBundlesList()
  File "/home/runner/work/CGGR/CGGR/cggr.py", line 28, in GetBundlesList
    r = requests.get(self.assetbundleInfoUrl)
  File "/opt/hostedtoolcache/Python/3.8.13/x64/lib/python3.8/site-packages/requests/api.py", line 73, in get
    return request("get", url, params=params, **kwargs)
  File "/opt/hostedtoolcache/Python/3.8.13/x64/lib/python3.8/site-packages/requests/api.py", line 59, in request
    return session.request(method=method, url=url, **kwargs)
  File "/opt/hostedtoolcache/Python/3.8.13/x64/lib/python3.8/site-packages/requests/sessions.py", line 587, in request
    resp = self.send(prep, **send_kwargs)
  File "/opt/hostedtoolcache/Python/3.8.13/x64/lib/python3.8/site-packages/requests/sessions.py", line 701, in send
    r = adapter.send(request, **kwargs)
  File "/opt/hostedtoolcache/Python/3.8.13/x64/lib/python3.8/site-packages/requests/adapters.py", line 547, in send
    raise ConnectionError(err, request=request)
requests.exceptions.ConnectionError: ('Connection aborted.', ConnectionResetError(104, 'Connection reset by peer'))
